Traceback (most recent call last):
  File "./ooiftp.py", line 46, in <module>
    sftp.cwd(path)
  File "/usr/local/lib/python3.6/site-packages/pysftp/__init__.py", line 524, in chdir
    self._sftp.chdir(remotepath)
  File "/usr/local/lib/python3.6/site-packages/paramiko/sftp_client.py", line 659, in chdir
    if not stat.S_ISDIR(self.stat(path).st_mode):
  File "/usr/local/lib/python3.6/site-packages/paramiko/sftp_client.py", line 493, in stat
    t, msg = self._request(CMD_STAT, path)
  File "/usr/local/lib/python3.6/site-packages/paramiko/sftp_client.py", line 813, in _request
    return self._read_response(num)
  File "/usr/local/lib/python3.6/site-packages/paramiko/sftp_client.py", line 865, in _read_response
    self._convert_status(msg)
  File "/usr/local/lib/python3.6/site-packages/paramiko/sftp_client.py", line 898, in _convert_status
    raise IOError(text)
OSError: Failure
