Traceback (most recent call last):
  File "./ooiftp.py", line 43, in <module>
    private_key=keyF, private_key_pass=keyP ) as sftp:
  File "/usr/local/lib/python3.6/site-packages/pysftp/__init__.py", line 132, in __init__
    self._tconnect['hostkey'] = self._cnopts.get_hostkey(host)
  File "/usr/local/lib/python3.6/site-packages/pysftp/__init__.py", line 71, in get_hostkey
    raise SSHException("No hostkey for host %s found." % host)
paramiko.ssh_exception.SSHException: No hostkey for host ftp.ooirsn.uw.edu found.
Exception ignored in: <bound method Connection.__del__ of <pysftp.Connection object at 0x7f4416f26710>>
Traceback (most recent call last):
  File "/usr/local/lib/python3.6/site-packages/pysftp/__init__.py", line 1013, in __del__
    self.close()
  File "/usr/local/lib/python3.6/site-packages/pysftp/__init__.py", line 784, in close
    if self._sftp_live:
AttributeError: 'Connection' object has no attribute '_sftp_live'
Traceback (most recent call last):
  File "./ooiftp.py", line 43, in <module>
    private_key=keyF, private_key_pass=keyP ) as sftp:
  File "/usr/local/lib/python3.6/site-packages/pysftp/__init__.py", line 132, in __init__
    self._tconnect['hostkey'] = self._cnopts.get_hostkey(host)
  File "/usr/local/lib/python3.6/site-packages/pysftp/__init__.py", line 71, in get_hostkey
    raise SSHException("No hostkey for host %s found." % host)
paramiko.ssh_exception.SSHException: No hostkey for host ftp.ooirsn.uw.edu found.
Exception ignored in: <bound method Connection.__del__ of <pysftp.Connection object at 0x7f49d4339710>>
Traceback (most recent call last):
  File "/usr/local/lib/python3.6/site-packages/pysftp/__init__.py", line 1013, in __del__
    self.close()
  File "/usr/local/lib/python3.6/site-packages/pysftp/__init__.py", line 784, in close
    if self._sftp_live:
AttributeError: 'Connection' object has no attribute '_sftp_live'
Traceback (most recent call last):
  File "/usr/local/lib/python3.6/site-packages/paramiko/channel.py", line 699, in recv
    out = self.in_buffer.read(nbytes, self.timeout)
  File "/usr/local/lib/python3.6/site-packages/paramiko/buffered_pipe.py", line 164, in read
    raise PipeTimeout()
paramiko.buffered_pipe.PipeTimeout

During handling of the above exception, another exception occurred:

Traceback (most recent call last):
  File "./ooiftp.py", line 57, in <module>
    ls = sftp.listdir_attr()
  File "/usr/local/lib/python3.6/site-packages/pysftp/__init__.py", line 610, in listdir_attr
    return sorted(self._sftp.listdir_attr(remotepath),
  File "/usr/local/lib/python3.6/site-packages/paramiko/sftp_client.py", line 246, in listdir_attr
    t, msg = self._request(CMD_READDIR, handle)
  File "/usr/local/lib/python3.6/site-packages/paramiko/sftp_client.py", line 813, in _request
    return self._read_response(num)
  File "/usr/local/lib/python3.6/site-packages/paramiko/sftp_client.py", line 843, in _read_response
    t, data = self._read_packet()
  File "/usr/local/lib/python3.6/site-packages/paramiko/sftp.py", line 201, in _read_packet
    x = self._read_all(4)
  File "/usr/local/lib/python3.6/site-packages/paramiko/sftp.py", line 185, in _read_all
    x = self.sock.recv(n)
  File "/usr/local/lib/python3.6/site-packages/paramiko/channel.py", line 701, in recv
    raise socket.timeout()
socket.timeout
